Workbook

Sheet Expenses
A1: T
B2: Rumors | L2: EXPENSES
B4: TOTAL EXPENSES | C4: s | I4: Estimated | L4: Actual
C5: Order Tracking | I5: =SUM(B39,H39,B73,H73,B80,B89,H89) -> 7248.55 | L5: =SUM(D39,J39,D73,J73,D80,D89,J89) -> 8272.1
B7: Scenic | C7: REF # | D7: PENDING CC | E7: ENC | F7: YTD | H7: Costumes | I7: REF # | J7: PENDING CC | K7: ENC | L7: YTD
B8: Curtis Lumber | C8: EP016349 | F8: 1153.59 | H8: Amazon Business, Inc | I8: EP016879 | L8: 156.31
B9: Grainger | C9: EP016576 | F9: 324.85 | H9: Amazon Business, Inc | I9: EP016994 | L9: 43.97
B10: Lowes for Pro's | C10: EP016575 | F10: 128.98 | H10: Amazon Business, Inc | I10: EP017057 | L10: 36.9
B11: Curtis Lumber | C11: EP016671 | F11: 248.64 | H11: Amazon Business, Inc | I11: EP017180 | L11: 439.82
B12: Curtis Lumber (Return) | C12: EP016671 | F12: -124.32 | H12: Amazon Business, Inc | I12: EP017323 | L12: 61.94
B13: Amazon Business, Inc | C13: EP016995 | F13: 30.56 | H13: Salvation Army (Reimbursement) | I13: EC000210 | L13: 44.43
B14: Amazon Business, Inc | C14: EP016996 | F14: 95.5 | H14: Amazon Business, Inc | I14: EP017419 | L14: 138.44
B15: Grainger | C15: EP017056 | F15: 43.4 | H15: Department AMEX (October) | I15: EC000111 | J15: ='Credit Card Purchases'!G10 -> 107.1
B16: Sherwin Williams | C16: EP017155 | F16: 545.21 | H16: The Costumer | I16: EP017512 | L16: 78.38
B17: Department AMEX (October) | C17: EC000111 | D17: ='Credit Card Purchases'!B11 -> 376.52 | H17: The Costumer (Shipping) | I17: EP017512 | L17: 7
B18: Purchasing AMEX (October) | C18: EC000352 | D18: ='Credit Card Purchases'!B14 -> 125.64 | H18: Department AMEX (November) | I18: EC000332 | L18: 286.3
B19: Home Depot | C19: EP017382 | F19: 157.64 | H19: WB Mason Company | I19: EP017819 | L19: 227.02
B20: Amazon Business, Inc | C20: EP017418 | F20: 148.89 | H20: Amazon Business, Inc (Return) | I20: EP017180 | L20: -30.99
B21: Amazon Business, Inc | C21: EP017479 | F21: 28.99 | H21: Amazon Business, Inc (Return) | I21: EP017419 | L21: -39.99
B22: Grainger | C22: EP017499 | F22: 141.02 | H22: Amazon Business, Inc (Return) | I22: EP017323 | L22: -5.99 | N22: -12.98?
B23: Grainger | C23: EP017561 | F23: 39.29 | H23: Amazon Business, Inc (Return) | I23: EP017180 | L23: -45.99
B24: Conway Entertainment | C24: EP018102 | F24: 150 | H24: Amazon Business, Inc (Return) | I24: EP017419 | L24: -23.79
B25: Purchasing AMEX (November) | C25: EC000363 | D25: ='Credit Card Purchases'!B43 -> 115.31 | H25: Best Cleaners | I25: EP018271 | L25: 223.2
B26: Amazon Business, Inc | C26: EP017438 | F26: 33.96
B27: Amazon Business, Inc | C27: EP017444 | F27: 13.98
B28: Amazon Business, Inc | C28: EP017604 | F28: 70.31
B29: Amazon Business, Inc | C29: EP017562 | E29: 12.47 | F29: 20.56
B30: Amazon Business, Inc | C30: EP017915 | E30: 39.99
B31: Theatre Dept 1 AMEX (December) | D31: 140.88
C38: TOTALS | D38: =SUM(D8:D37) -> 758.35 | E38: =SUM(E8:E37) -> 52.46 | F38: =SUM(F8:F37) -> 3251.05 | I38: TOTALS | J38: =SUM(J8:J37) -> 107.1 | K38: =SUM(K8:K37) -> 0 | L38: =SUM(L8:L37) -> 1596.96
B39: 2500 | C39: ALL TOTAL | D39: =SUM(D38:F38) -> 4061.86 | H39: 1500 | I39: ALL TOTAL | J39: =SUM(J38:L38) -> 1704.06
B41: Lighting | C41: REF # | D41: PENDING CC | E41: ENC | F41: YTD | H41: Sound | I41: REF # | J41: PENDING CC | K41: ENC | L41: YTD
B42: BMI Supply | C42: EP017425 | F42: 266 | H42: B & H Foto & Electronics Corp. | I42: EP018236 | K42: 112.48
B43: BMI Supply (Shipping) | C43: EP017425 | F43: 18.5
B44: B & H Foto & Electronics Corp. | C44: EP017560 | F44: 96.07
B45: Purchasing AMEX (November) | C45: EC000363 | D45: ='Credit Card Purchases'!C43 -> 35.92
C72: TOTALS | D72: =SUM(D42:D71) -> 35.92 | E72: =SUM(E42:E71) -> 0 | F72: =SUM(F42:F71) -> 380.57 | I72: TOTALS | J72: =SUM(J42:J71) -> 0 | K72: =SUM(K42:K71) -> 112.48 | L72: =SUM(L42:L71) -> 0
B73: 1000 | C73: ALL TOTAL | D73: =SUM(D72:F72) -> 416.49 | H73: 100 | I73: ALL TOTAL | J73: =SUM(J72:L72) -> 112.48
B75: Rights | C75: REF # | D75: PENDING CC | E75: ENC | F75: YTD | H75: Miscellaneous | I75: REF # | J75: PENDING CC | K75: ENC | L75: YTD
B76: Concord Theatrical (Rights) | C76: EP012471 | F76: 910 | H76: KCACTF Registration | I76: J0179555 | L76: 300
...

Sheet Credit Card Purchases
B1: 11300 (Scenic) | C1: 11301 (Lighting) | D1: 11302 (Sound) | E1: 11303 (Video) | F1: 11304 (Props) | G1: 11305 (Costumes) | H1: 11306 (Music) | I1: 11307 (Ticketing Supplies) | J1: 11308 (Production Supplies) | K1: 11220 (Lodging) | L1: 11412 (Meals with Guests)
A2: EC000011 - October (Department)
A3: Waves SuperRack Performer | J3: 64.35
A4: Receipt for Home Depot | B4: 47.94
A5: Ollies Bargain Outlet | B5: 251.64
A6: Waves Ultimate - Annual | J6: 162.49
A7: Lumber for Fall Production | B7: 76.94
A8: Costume Supplies for Fall Production | G8: 108.19
A9: Costume Supplies for Fall Production | G9: 107.79
A10: Costume Supplies for Fall Production | G10: 107.1
A11: Totals: | B11: =SUM(B3:B10) -> 376.52 | C11: =SUM(C3:C10) -> 0 | D11: =SUM(D3:D10) -> 0 | E11: =SUM(E3:E10) -> 0 | F11: =SUM(F3:F10) -> 0 | G11: =SUM(G3:G10) -> 323.08 | H11: =SUM(H3:H10) -> 0 | I11: =SUM(I3:I10) -> 0 | J11: =SUM(J3:J10) -> 226.84 | M11: Monthly Total: | N11: =SUM(B11:L11) -> 926.44
A12: EC000352 - October (Purchasing)
A13: Lowes Receipt - Scenic | B13: 125.64
A14: Totals: | B14: =SUM(B13) -> 125.64 | C14: =SUM(C13) -> 0 | D14: =SUM(D13) -> 0 | E14: =SUM(E13) -> 0 | F14: =SUM(F13) -> 0 | G14: =SUM(G13) -> 0 | H14: =SUM(H13) -> 0 | I14: =SUM(I13) -> 0 | J14: =SUM(J13) -> 0 | M14: Monthly Total: | N14: =SUM(B14:L14) -> 125.64
A15: EC000332 - November (Department)
A16: Hobby Lobby Receipt - Costumes | G16: 12.72
A17: Michaels Receipt - Costumes | G17: 7.58
A18: Walmart Receipt - Costumes | G18: 90.42
A19: Hobby Lobby Receipt - Costumes | G19: 9.86
A20: Walmart Receipt - Costumes | G20: 50.52
A21: Burlington Receipt - Costumes | G21: 24.99
A22: DSW Receipt - Costumes | G22: 41.99
A23: Michaels Receipt - Costumes | G23: 13.98
A24: Walmart Receipt - Costumes | G24: 34.24
A25: Microtel Receipt - Lodging | K25: 457.8
A26: Microtel Receipt - Lodging | K26: 457.8
L27: 113
A28: Totals: | B28: =SUM(B16:B27) -> 0 | C28: =SUM(C16:C27) -> 0 | D28: =SUM(D16:D27) -> 0 | E28: =SUM(E16:E27) -> 0 | F28: =SUM(F16:F27) -> 0 | G28: =SUM(G16:G27) -> 286.3 | H28: =SUM(H16:H27) -> 0 | I28: =SUM(I16:I27) -> 0 | ... L28: =SUM(L16:L27) -> 113 | M28: Monthly Total: | N28: =SUM(B28:L28) -> 1314.9
A29: EC000363 - November (Purchasing)
A30: Homegoods Receipt - Props | F30: 9.98
A31: Lowes Receipt - Lighting | C31: 35.92
A32: Lowes Receipt - Scenic | B32: 27.24
A33: Michaels Receipt - Scenic | B33: 26.98
A34: Home Depot Receipt - Scenic | B34: 16.48
A35: Home Depot Receipt - Props | F35: 31.42
A36: Sherwing Williams Receipt - Scenic | B36: 29.85
A37: Walmart Receipt - Props | F37: 101.46
A38: Walmart Receipt - Props | F38: 8.01
A39: Walmart Receipt - Scenic | B39: 20.64
A40: Walmart Receipt - Props | F40: 19.73
...
